[32m2023-03-31 04:58:21 +0000[0m - dagster - [34mDEBUG[0m - __ASSET_JOB - c05554b9-d0c1-4272-8b1d-977e1b0c4420 - 21406 - LOGS_CAPTURED - Started capturing logs in process (pid: 21406).
[32m2023-03-31 04:58:21 +0000[0m - dagster - [34mDEBUG[0m - __ASSET_JOB - c05554b9-d0c1-4272-8b1d-977e1b0c4420 - 21406 - scrape_popup_links - STEP_START - Started execution of step "scrape_popup_links".
[32m2023-03-31 04:58:22 +0000[0m - dagster - [34mERROR[0m - [31m__ASSET_JOB - c05554b9-d0c1-4272-8b1d-977e1b0c4420 - 21406 - scrape_popup_links - STEP_FAILURE - Execution of step "scrape_popup_links" failed.

dagster._core.errors.DagsterExecutionStepExecutionError: Error occurred while executing op "scrape_popup_links"::

google.api_core.exceptions.NotFound: 404 POST https://bigquery.googleapis.com/bigquery/v2/projects/dagstertest-382218/datasets/TestScrapeDataset/tables/popup_links/insertAll?prettyPrint=false: Table is truncated.

Stack Trace:
  File "/home/dmytro_fedoru/.local/lib/python3.9/site-packages/dagster/_core/execution/plan/utils.py", line 54, in op_execution_error_boundary
    yield
  File "/home/dmytro_fedoru/.local/lib/python3.9/site-packages/dagster/_utils/__init__.py", line 439, in iterate_with_context
    next_output = next(iterator)
  File "/home/dmytro_fedoru/.local/lib/python3.9/site-packages/dagster/_core/execution/plan/compute_generator.py", line 122, in _coerce_solid_compute_fn_to_iterator
    result = invoke_compute_fn(
  File "/home/dmytro_fedoru/.local/lib/python3.9/site-packages/dagster/_core/execution/plan/compute_generator.py", line 116, in invoke_compute_fn
    return fn(context, **args_to_pass) if context_arg_provided else fn(**args_to_pass)
  File "/home/dmytro_fedoru/dag-scrape-project/dag_scrape_project/assets/scrape_popup_links.py", line 28, in scrape_popup_links
    errors = client.insert_rows_json(table_id, records)
  File "/usr/local/lib/python3.9/dist-packages/google/cloud/bigquery/client.py", line 3674, in insert_rows_json
    response = self._call_api(
  File "/usr/local/lib/python3.9/dist-packages/google/cloud/bigquery/client.py", line 797, in _call_api
    return call()
  File "/usr/local/lib/python3.9/dist-packages/google/api_core/retry.py", line 349, in retry_wrapped_func
    return retry_target(
  File "/usr/local/lib/python3.9/dist-packages/google/api_core/retry.py", line 191, in retry_target
    return target()
  File "/usr/local/lib/python3.9/dist-packages/google/cloud/_http/__init__.py", line 494, in api_request
    raise exceptions.from_http_response(response)
[0m
