[32m2023-03-31 14:27:31 +0000[0m - dagster - [34mDEBUG[0m - __ASSET_JOB - 006c075b-0dcd-42fb-9b6d-220485ddf567 - 105237 - LOGS_CAPTURED - Started capturing logs in process (pid: 105237).
[32m2023-03-31 14:27:31 +0000[0m - dagster - [34mDEBUG[0m - __ASSET_JOB - 006c075b-0dcd-42fb-9b6d-220485ddf567 - 105237 - scrape_listings - STEP_START - Started execution of step "scrape_listings".
[32m2023-03-31 14:27:32 +0000[0m - dagster - [34mERROR[0m - [31m__ASSET_JOB - 006c075b-0dcd-42fb-9b6d-220485ddf567 - 105237 - scrape_listings - STEP_FAILURE - Execution of step "scrape_listings" failed.

dagster._core.errors.DagsterExecutionStepExecutionError: Error occurred while executing op "scrape_listings"::

google.api_core.exceptions.Forbidden: 403 POST https://bigquery.googleapis.com/bigquery/v2/projects/dagstertest-382218/datasets/TestScrapeDataset/tables/listings/insertAll?prettyPrint=false: Request had insufficient authentication scopes.

Stack Trace:
  File "/home/dmytro_fedoru/venv/lib/python3.9/site-packages/dagster/_core/execution/plan/utils.py", line 54, in op_execution_error_boundary
    yield
  File "/home/dmytro_fedoru/venv/lib/python3.9/site-packages/dagster/_utils/__init__.py", line 439, in iterate_with_context
    next_output = next(iterator)
  File "/home/dmytro_fedoru/venv/lib/python3.9/site-packages/dagster/_core/execution/plan/compute_generator.py", line 122, in _coerce_solid_compute_fn_to_iterator
    result = invoke_compute_fn(
  File "/home/dmytro_fedoru/venv/lib/python3.9/site-packages/dagster/_core/execution/plan/compute_generator.py", line 116, in invoke_compute_fn
    return fn(context, **args_to_pass) if context_arg_provided else fn(**args_to_pass)
  File "/home/dmytro_fedoru/dagster-dbt/dag-scrape-project/dag_scrape_project/assets/scrape_listings.py", line 26, in scrape_listings
    errors = client.insert_rows_json(table_id, records)
  File "/home/dmytro_fedoru/venv/lib/python3.9/site-packages/google/cloud/bigquery/client.py", line 3688, in insert_rows_json
    response = self._call_api(
  File "/home/dmytro_fedoru/venv/lib/python3.9/site-packages/google/cloud/bigquery/client.py", line 813, in _call_api
    return call()
  File "/home/dmytro_fedoru/venv/lib/python3.9/site-packages/google/api_core/retry.py", line 349, in retry_wrapped_func
    return retry_target(
  File "/home/dmytro_fedoru/venv/lib/python3.9/site-packages/google/api_core/retry.py", line 191, in retry_target
    return target()
  File "/home/dmytro_fedoru/venv/lib/python3.9/site-packages/google/cloud/_http/__init__.py", line 494, in api_request
    raise exceptions.from_http_response(response)
[0m
